<?xml version="1.0" encoding="UTF-8"?>
<sdf version='1.10'>
  <model name='buggy'>
    <self_collide>false</self_collide>
    <static>false</static>

    <link name="base_footprint"/>
    
    <joint name="base_joint" type="fixed">
      <parent>base_footprint</parent>
      <child>base_link</child>
      <pose>0.0 0.0 -0.04 0 0 0</pose>
    </joint>

    <link name='base_link'>
      <inertial>
        <pose>0.5 0 0.125 0 0 0</pose>
        <mass>1</mass>
        <inertia>
          <ixx>0.026041666666666661</ixx>
          <ixy>0</ixy>
          <ixz>0</ixz>
          <iyy>0.08854166666666663</iyy>
          <iyz>0</iyz>
          <izz>0.1041666666666666</izz>
        </inertia>
      </inertial>
      <collision name='base_link_fixed_joint_lump__chassis_link_collision'>
        <pose>0.5 0 0.125 0 0 0</pose>
        <geometry>
          <box>
            <size>1 0.5 0.25</size>
          </box>
        </geometry>
      </collision>
      <visual name='base_link_fixed_joint_lump__chassis_link_visual'>
        <pose>0.5 0 0.125 0 0 0</pose>
        <geometry>
          <box>
            <size>1 0.5 0.25</size>
          </box>
        </geometry>
      </visual>
    </link>
    <joint name='chassis_to_left_wheel1_joint' type='revolute'>
      <pose relative_to='base_link'>0.83333333333333326 0.2857142857142857 0 -1.5707963267948959 0 0</pose>
      <parent>base_link</parent>
      <child>left_wheel1_link</child>
      <axis>
        <xyz>0 0 1</xyz>
        <limit>
          <lower>-inf</lower>
          <upper>inf</upper>
        </limit>
        <dynamics>
          <spring_reference>0</spring_reference>
          <spring_stiffness>0</spring_stiffness>
        </dynamics>
      </axis>
    </joint>
    <link name='left_wheel1_link'>
      <pose relative_to='chassis_to_left_wheel1_joint'>0 0 0 0 0 0</pose>
      <inertial>
        <pose>0 0 0 0 0 0</pose>
        <mass>0.25</mass>
        <inertia>
          <ixx>0.00073129251700680274</ixx>
          <ixy>0</ixy>
          <ixz>0</ixz>
          <iyy>0.00073129251700680274</iyy>
          <iyz>0</iyz>
          <izz>0.00125</izz>
        </inertia>
      </inertial>
      <collision name='left_wheel1_link_collision'>
        <pose>0 0 0 0 0 0</pose>
        <geometry>
          <cylinder>
            <length>0.071428571428571425</length>
            <radius>0.10000000000000001</radius>
          </cylinder>
        </geometry>
      </collision>
      <visual name='left_wheel1_link_visual'>
        <pose>0 0 0 0 0 0</pose>
        <geometry>
          <cylinder>
            <length>0.071428571428571425</length>
            <radius>0.10000000000000001</radius>
          </cylinder>
        </geometry>
      </visual>
    </link>
    <joint name='chassis_to_left_wheel2_joint' type='revolute'>
      <pose relative_to='base_link'>0.16666666666666671 0.2857142857142857 0 -1.5707963267948959 0 0</pose>
      <parent>base_link</parent>
      <child>left_wheel2_link</child>
      <axis>
        <xyz>0 0 1</xyz>
        <limit>
          <lower>-inf</lower>
          <upper>inf</upper>
        </limit>
        <dynamics>
          <spring_reference>0</spring_reference>
          <spring_stiffness>0</spring_stiffness>
        </dynamics>
      </axis>
    </joint>
    <link name='left_wheel2_link'>
      <pose relative_to='chassis_to_left_wheel2_joint'>0 0 0 0 0 0</pose>
      <inertial>
        <pose>0 0 0 0 0 0</pose>
        <mass>0.25</mass>
        <inertia>
          <ixx>0.00073129251700680274</ixx>
          <ixy>0</ixy>
          <ixz>0</ixz>
          <iyy>0.00073129251700680274</iyy>
          <iyz>0</iyz>
          <izz>0.00125</izz>
        </inertia>
      </inertial>
      <collision name='left_wheel2_link_collision'>
        <pose>0 0 0 0 0 0</pose>
        <geometry>
          <cylinder>
            <length>0.071428571428571425</length>
            <radius>0.10000000000000001</radius>
          </cylinder>
        </geometry>
      </collision>
      <visual name='left_wheel2_link_visual'>
        <pose>0 0 0 0 0 0</pose>
        <geometry>
          <cylinder>
            <length>0.071428571428571425</length>
            <radius>0.10000000000000001</radius>
          </cylinder>
        </geometry>
      </visual>
    </link>
    <joint name='chassis_to_right_wheel1_joint' type='revolute'>
      <pose relative_to='base_link'>0.83333333333333326 -0.2857142857142857 0 1.5707963267948959 0 0</pose>
      <parent>base_link</parent>
      <child>right_wheel1_link</child>
      <axis>
        <xyz>0 0 -1</xyz>
        <limit>
          <lower>-inf</lower>
          <upper>inf</upper>
        </limit>
        <dynamics>
          <spring_reference>0</spring_reference>
          <spring_stiffness>0</spring_stiffness>
        </dynamics>
      </axis>
    </joint>
    <link name='right_wheel1_link'>
      <pose relative_to='chassis_to_right_wheel1_joint'>0 0 0 0 0 0</pose>
      <inertial>
        <pose>0 0 0 0 0 0</pose>
        <mass>0.25</mass>
        <inertia>
          <ixx>0.00073129251700680274</ixx>
          <ixy>0</ixy>
          <ixz>0</ixz>
          <iyy>0.00073129251700680274</iyy>
          <iyz>0</iyz>
          <izz>0.00125</izz>
        </inertia>
      </inertial>
      <collision name='right_wheel1_link_collision'>
        <pose>0 0 0 0 0 0</pose>
        <geometry>
          <cylinder>
            <length>0.071428571428571425</length>
            <radius>0.10000000000000001</radius>
          </cylinder>
        </geometry>
      </collision>
      <visual name='right_wheel1_link_visual'>
        <pose>0 0 0 0 0 0</pose>
        <geometry>
          <cylinder>
            <length>0.071428571428571425</length>
            <radius>0.10000000000000001</radius>
          </cylinder>
        </geometry>
      </visual>
    </link>
    <joint name='chassis_to_right_wheel2_joint' type='revolute'>
      <pose relative_to='base_link'>0.16666666666666671 -0.2857142857142857 0 1.5707963267948959 0 0</pose>
      <parent>base_link</parent>
      <child>right_wheel2_link</child>
      <axis>
        <xyz>0 0 -1</xyz>
        <limit>
          <lower>-inf</lower>
          <upper>inf</upper>
        </limit>
        <dynamics>
          <spring_reference>0</spring_reference>
          <spring_stiffness>0</spring_stiffness>
        </dynamics>
      </axis>
    </joint>
    <link name='right_wheel2_link'>
      <pose relative_to='chassis_to_right_wheel2_joint'>0 0 0 0 0 0</pose>
      <inertial>
        <pose>0 0 0 0 0 0</pose>
        <mass>0.25</mass>
        <inertia>
          <ixx>0.00073129251700680274</ixx>
          <ixy>0</ixy>
          <ixz>0</ixz>
          <iyy>0.00073129251700680274</iyy>
          <iyz>0</iyz>
          <izz>0.00125</izz>
        </inertia>
      </inertial>
      <collision name='right_wheel2_link_collision'>
        <pose>0 0 0 0 0 0</pose>
        <geometry>
          <cylinder>
            <length>0.071428571428571425</length>
            <radius>0.10000000000000001</radius>
          </cylinder>
        </geometry>
      </collision>
      <visual name='right_wheel2_link_visual'>
        <pose>0 0 0 0 0 0</pose>
        <geometry>
          <cylinder>
            <length>0.071428571428571425</length>
            <radius>0.10000000000000001</radius>
          </cylinder>
        </geometry>
      </visual>
    </link>

<!-- camera stuff -->
    <joint name="camera_joint" type="fixed">
      <parent>base_link</parent>
      <child>camera_link</child>
    </joint>
    <link name="camera_link">
      <!-- <pose>2.0 0 1.25 0 0 0</pose> -->
      <pose>1.0 0 0.25 0 0 0</pose>
      <inertial>
        <pose>0 0 0 0 0 0</pose>
        <mass>0.01</mass>
        <inertia>
          <ixx>0.00000130666</ixx> <!-- (.01/12)*(.028^2+.028^2) -->
          <ixy>0</ixy>
          <ixz>0</ixz>
          <iyy>0.00000130666</iyy> <!-- (.01/12)*(.028^2+.028^2) -->
          <iyz>0</iyz>
          <izz>0.00000130666</izz> <!-- (.01/12)*(.028^2+.028^2) -->
        </inertia>
      </inertial>
      <visual name="camera_housing">
        <pose>.013 0 0 0 0 0</pose>
        <geometry>
          <box>
            <size>.008 .028 .028</size>
          </box>
        </geometry>
        <material>
          <diffuse>1.0 1.0 1.0</diffuse>
          <specular>1.0 1.0 1.0</specular>
        </material>
      </visual>
      <visual name="camera_housing_mount">
        <pose>.008 0 0 0 0 0</pose>
        <geometry>
          <box>
            <size>.008 .014 .01</size>
          </box>
        </geometry>
        <material>
          <diffuse>1.0 1.0 1.0</diffuse>
          <specular>1.0 1.0 1.0</specular>
        </material>
      </visual>
      <visual name="camera_lens">
        <pose>.016 0 .006 0 1.57079632679 0</pose>
        <geometry>
          <cylinder>
            <length>0.003</length>
            <radius>0.004</radius>
          </cylinder>
        </geometry>
      </visual>
      <sensor name="ov5645" type="camera">
        <pose>.016 0 .006 0 0 0</pose>
        <camera>
          <image>
            <width>320</width>
            <height>240</height>
            <format>B8G8R8</format>
          </image>
          <clip>
            <near>0.05</near>
            <far>100</far>
          </clip>
          <optical_frame_id>camera_link_optical</optical_frame_id>
        </camera>
        <always_on>1</always_on>
        <update_rate>30</update_rate>
        <visualize>true</visualize>
        <topic>/camera/image_raw</topic>
      </sensor>
    </link>

<plugin
    filename="gz-sim-diff-drive-system"
    name="gz::sim::systems::DiffDrive">
    <left_joint>chassis_to_left_wheel1_joint</left_joint>
    <right_joint>chassis_to_right_wheel1_joint</right_joint>
    <left_joint>chassis_to_left_wheel2_joint</left_joint>
    <right_joint>chassis_to_right_wheel2_joint</right_joint>
    <wheel_separation>1.2</wheel_separation>
    <wheel_radius>0.4</wheel_radius>
    <odom_publish_frequency>1</odom_publish_frequency>
    <topic>cmd_vel</topic>
</plugin>

  </model>
</sdf>
