<sdf version='1.11'>
  <model name='ekalavya'>
    <link name='base_link'>
      <inertial>
        <pose>0.5 0 0.125 0 0 0</pose>
        <mass>1</mass>
        <inertia>
          <ixx>0.026041666666666661</ixx>
          <ixy>0</ixy>
          <ixz>0</ixz>
          <iyy>0.08854166666666663</iyy>
          <iyz>0</iyz>
          <izz>0.1041666666666666</izz>
        </inertia>
      </inertial>
      <collision name='base_link_fixed_joint_lump__chassis_link_collision'>
        <pose>0.5 0 0.125 0 0 0</pose>
        <geometry>
          <box>
            <size>1 0.5 0.25</size>
          </box>
        </geometry>
      </collision>
      <visual name='base_link_fixed_joint_lump__chassis_link_visual'>
        <pose>0.5 0 0.125 0 0 0</pose>
        <geometry>
          <box>
            <size>1 0.5 0.25</size>
          </box>
        </geometry>
      </visual>
    </link>
    <joint name='chassis_to_left_wheel1_joint' type='revolute'>
      <pose relative_to='base_link'>0.83333333333333326 0.2857142857142857 0 -1.5707963267948959 0 0</pose>
      <parent>base_link</parent>
      <child>left_wheel1_link</child>
      <axis>
        <xyz>0 0 1</xyz>
        <limit>
          <lower>-inf</lower>
          <upper>inf</upper>
        </limit>
        <dynamics>
          <spring_reference>0</spring_reference>
          <spring_stiffness>0</spring_stiffness>
        </dynamics>
      </axis>
    </joint>
    <link name='left_wheel1_link'>
      <pose relative_to='chassis_to_left_wheel1_joint'>0 0 0 0 0 0</pose>
      <inertial>
        <pose>0 0 0 0 0 0</pose>
        <mass>0.25</mass>
        <inertia>
          <ixx>0.00073129251700680274</ixx>
          <ixy>0</ixy>
          <ixz>0</ixz>
          <iyy>0.00073129251700680274</iyy>
          <iyz>0</iyz>
          <izz>0.00125</izz>
        </inertia>
      </inertial>
      <collision name='left_wheel1_link_collision'>
        <pose>0 0 0 0 0 0</pose>
        <geometry>
          <cylinder>
            <length>0.071428571428571425</length>
            <radius>0.10000000000000001</radius>
          </cylinder>
        </geometry>
      </collision>
      <visual name='left_wheel1_link_visual'>
        <pose>0 0 0 0 0 0</pose>
        <geometry>
          <cylinder>
            <length>0.071428571428571425</length>
            <radius>0.10000000000000001</radius>
          </cylinder>
        </geometry>
      </visual>
    </link>
    <joint name='chassis_to_left_wheel2_joint' type='revolute'>
      <pose relative_to='base_link'>0.16666666666666671 0.2857142857142857 0 -1.5707963267948959 0 0</pose>
      <parent>base_link</parent>
      <child>left_wheel2_link</child>
      <axis>
        <xyz>0 0 1</xyz>
        <limit>
          <lower>-inf</lower>
          <upper>inf</upper>
        </limit>
        <dynamics>
          <spring_reference>0</spring_reference>
          <spring_stiffness>0</spring_stiffness>
        </dynamics>
      </axis>
    </joint>
    <link name='left_wheel2_link'>
      <pose relative_to='chassis_to_left_wheel2_joint'>0 0 0 0 0 0</pose>
      <inertial>
        <pose>0 0 0 0 0 0</pose>
        <mass>0.25</mass>
        <inertia>
          <ixx>0.00073129251700680274</ixx>
          <ixy>0</ixy>
          <ixz>0</ixz>
          <iyy>0.00073129251700680274</iyy>
          <iyz>0</iyz>
          <izz>0.00125</izz>
        </inertia>
      </inertial>
      <collision name='left_wheel2_link_collision'>
        <pose>0 0 0 0 0 0</pose>
        <geometry>
          <cylinder>
            <length>0.071428571428571425</length>
            <radius>0.10000000000000001</radius>
          </cylinder>
        </geometry>
      </collision>
      <visual name='left_wheel2_link_visual'>
        <pose>0 0 0 0 0 0</pose>
        <geometry>
          <cylinder>
            <length>0.071428571428571425</length>
            <radius>0.10000000000000001</radius>
          </cylinder>
        </geometry>
      </visual>
    </link>
    <joint name='chassis_to_right_wheel1_joint' type='revolute'>
      <pose relative_to='base_link'>0.83333333333333326 -0.2857142857142857 0 1.5707963267948959 0 0</pose>
      <parent>base_link</parent>
      <child>right_wheel1_link</child>
      <axis>
        <xyz>0 0 -1</xyz>
        <limit>
          <lower>-inf</lower>
          <upper>inf</upper>
        </limit>
        <dynamics>
          <spring_reference>0</spring_reference>
          <spring_stiffness>0</spring_stiffness>
        </dynamics>
      </axis>
    </joint>
    <link name='right_wheel1_link'>
      <pose relative_to='chassis_to_right_wheel1_joint'>0 0 0 0 0 0</pose>
      <inertial>
        <pose>0 0 0 0 0 0</pose>
        <mass>0.25</mass>
        <inertia>
          <ixx>0.00073129251700680274</ixx>
          <ixy>0</ixy>
          <ixz>0</ixz>
          <iyy>0.00073129251700680274</iyy>
          <iyz>0</iyz>
          <izz>0.00125</izz>
        </inertia>
      </inertial>
      <collision name='right_wheel1_link_collision'>
        <pose>0 0 0 0 0 0</pose>
        <geometry>
          <cylinder>
            <length>0.071428571428571425</length>
            <radius>0.10000000000000001</radius>
          </cylinder>
        </geometry>
      </collision>
      <visual name='right_wheel1_link_visual'>
        <pose>0 0 0 0 0 0</pose>
        <geometry>
          <cylinder>
            <length>0.071428571428571425</length>
            <radius>0.10000000000000001</radius>
          </cylinder>
        </geometry>
      </visual>
    </link>
    <joint name='chassis_to_right_wheel2_joint' type='revolute'>
      <pose relative_to='base_link'>0.16666666666666671 -0.2857142857142857 0 1.5707963267948959 0 0</pose>
      <parent>base_link</parent>
      <child>right_wheel2_link</child>
      <axis>
        <xyz>0 0 -1</xyz>
        <limit>
          <lower>-inf</lower>
          <upper>inf</upper>
        </limit>
        <dynamics>
          <spring_reference>0</spring_reference>
          <spring_stiffness>0</spring_stiffness>
        </dynamics>
      </axis>
    </joint>
    <link name='right_wheel2_link'>
      <pose relative_to='chassis_to_right_wheel2_joint'>0 0 0 0 0 0</pose>
      <inertial>
        <pose>0 0 0 0 0 0</pose>
        <mass>0.25</mass>
        <inertia>
          <ixx>0.00073129251700680274</ixx>
          <ixy>0</ixy>
          <ixz>0</ixz>
          <iyy>0.00073129251700680274</iyy>
          <iyz>0</iyz>
          <izz>0.00125</izz>
        </inertia>
      </inertial>
      <collision name='right_wheel2_link_collision'>
        <pose>0 0 0 0 0 0</pose>
        <geometry>
          <cylinder>
            <length>0.071428571428571425</length>
            <radius>0.10000000000000001</radius>
          </cylinder>
        </geometry>
      </collision>
      <visual name='right_wheel2_link_visual'>
        <pose>0 0 0 0 0 0</pose>
        <geometry>
          <cylinder>
            <length>0.071428571428571425</length>
            <radius>0.10000000000000001</radius>
          </cylinder>
        </geometry>
      </visual>
    </link>
    <frame name='base_to_chassis_joint' attached_to='base_link'>
      <pose>0.5 0 0.125 0 0 0</pose>
    </frame>
    <frame name='chassis_link' attached_to='base_to_chassis_joint'>
      <pose>0 0 0 0 0 0</pose>
    </frame>
  </model>
</sdf>
