<?xml version="1.0" ?>
<!-- =================================================================================== -->
<!-- |    This document was autogenerated by xacro from robot.urdf.xacro               | -->
<!-- |    EDITING THIS FILE BY HAND IS NOT RECOMMENDED                                 | -->
<!-- =================================================================================== -->
<robot name="ekalavya">
  <!-- end of macros -->
  <link name="base_link"/>
  <joint name="base_to_chassis_joint" type="fixed">
    <parent link="base_link"/>
    <child link="chassis_link"/>
    <origin rpy="0.0 0.0 0.0" xyz="0.5 0.0 0.125"/>
  </joint>
  <link name="chassis_link">
    <visual>
      <origin rpy="0.0 0.0 0.0" xyz="0.0 0.0 0.0"/>
      <geometry>
        <box size="1 0.5 0.25"/>
      </geometry>
    </visual>
    <collision>
      <origin rpy="0.0 0.0 0.0" xyz="0.0 0.0 0.0"/>
      <geometry>
        <box size="1 0.5 0.25"/>
      </geometry>
    </collision>
    <inertial>
      <origin rpy="0 0 0" xyz="0.0 0 0"/>
      <mass value="1"/>
      <inertia ixx="0.026041666666666664" ixy="0.0" ixz="0.0" iyy="0.08854166666666666" iyz="0.0" izz="0.10416666666666666"/>
    </inertial>
  </link>
  <!-- left wheel1 -->
  <joint name="chassis_to_left_wheel1_joint" type="continuous">
    <parent link="chassis_link"/>
    <child link="left_wheel1_link"/>
    <axis xyz="0 0 1"/>
    <origin rpy="-1.5707963267948966 0 0" xyz="0.3333333333333333 0.2857142857142857 -0.125"/>
  </joint>
  <link name="left_wheel1_link">
    <visual>
      <origin rpy="0.0 0.0 0.0" xyz="0.0 0.0 0.0"/>
      <geometry>
        <cylinder length="0.07142857142857142" radius="0.1"/>
      </geometry>
    </visual>
    <collision>
      <origin rpy="0.0 0.0 0.0" xyz="0.0 0.0 0.0"/>
      <geometry>
        <cylinder length="0.07142857142857142" radius="0.1"/>
      </geometry>
    </collision>
    <inertial>
      <origin rpy="0.0 0.0 0.0" xyz="0.0 0.0 0.0"/>
      <mass value="0.25"/>
      <inertia ixx="0.0007312925170068027" ixy="0.0" ixz="0.0" iyy="0.0007312925170068027" iyz="0.0" izz="0.0012500000000000002"/>
    </inertial>
  </link>
  <!-- left wheel2 -->
  <joint name="chassis_to_left_wheel2_joint" type="continuous">
    <parent link="chassis_link"/>
    <child link="left_wheel2_link"/>
    <axis xyz="0 0 1"/>
    <origin rpy="-1.5707963267948966 0 0" xyz="-0.3333333333333333 0.2857142857142857 -0.125"/>
  </joint>
  <link name="left_wheel2_link">
    <visual>
      <origin rpy="0.0 0.0 0.0" xyz="0.0 0.0 0.0"/>
      <geometry>
        <cylinder length="0.07142857142857142" radius="0.1"/>
      </geometry>
    </visual>
    <collision>
      <origin rpy="0.0 0.0 0.0" xyz="0.0 0.0 0.0"/>
      <geometry>
        <cylinder length="0.07142857142857142" radius="0.1"/>
      </geometry>
    </collision>
    <inertial>
      <origin rpy="0.0 0.0 0.0" xyz="0.0 0.0 0.0"/>
      <mass value="0.25"/>
      <inertia ixx="0.0007312925170068027" ixy="0.0" ixz="0.0" iyy="0.0007312925170068027" iyz="0.0" izz="0.0012500000000000002"/>
    </inertial>
  </link>
  <!-- right wheel1 -->
  <joint name="chassis_to_right_wheel1_joint" type="continuous">
    <parent link="chassis_link"/>
    <child link="right_wheel1_link"/>
    <axis xyz="0 0 -1"/>
    <origin rpy="1.5707963267948966 0 0" xyz="0.3333333333333333 -0.2857142857142857 -0.125"/>
  </joint>
  <link name="right_wheel1_link">
    <visual>
      <origin rpy="0.0 0.0 0.0" xyz="0.0 0.0 0.0"/>
      <geometry>
        <cylinder length="0.07142857142857142" radius="0.1"/>
      </geometry>
    </visual>
    <collision>
      <origin rpy="0.0 0.0 0.0" xyz="0.0 0.0 0.0"/>
      <geometry>
        <cylinder length="0.07142857142857142" radius="0.1"/>
      </geometry>
    </collision>
    <inertial>
      <origin rpy="0.0 0.0 0.0" xyz="0.0 0.0 0.0"/>
      <mass value="0.25"/>
      <inertia ixx="0.0007312925170068027" ixy="0.0" ixz="0.0" iyy="0.0007312925170068027" iyz="0.0" izz="0.0012500000000000002"/>
    </inertial>
  </link>
  <!-- left wheel2 -->
  <joint name="chassis_to_right_wheel2_joint" type="continuous">
    <parent link="chassis_link"/>
    <child link="right_wheel2_link"/>
    <axis xyz="0 0 -1"/>
    <origin rpy="1.5707963267948966 0 0" xyz="-0.3333333333333333 -0.2857142857142857 -0.125"/>
  </joint>
  <link name="right_wheel2_link">
    <visual>
      <origin rpy="0.0 0.0 0.0" xyz="0.0 0.0 0.0"/>
      <geometry>
        <cylinder length="0.07142857142857142" radius="0.1"/>
      </geometry>
    </visual>
    <collision>
      <origin rpy="0.0 0.0 0.0" xyz="0.0 0.0 0.0"/>
      <geometry>
        <cylinder length="0.07142857142857142" radius="0.1"/>
      </geometry>
    </collision>
    <inertial>
      <origin rpy="0.0 0.0 0.0" xyz="0.0 0.0 0.0"/>
      <mass value="0.25"/>
      <inertia ixx="0.0007312925170068027" ixy="0.0" ixz="0.0" iyy="0.0007312925170068027" iyz="0.0" izz="0.0012500000000000002"/>
    </inertial>
  </link>
</robot>
