<?xml version="1.0" ?>
<robot name="ekalavya">
  <!-- i can put this macros in another file -->
  <!-- end of macros -->
  <link name="base_link"/>
  <joint name="base_to_chassis_joint" type="fixed">
    <parent link="base_link"/>
    <child link="chassis_link"/>
    <origin rpy="0.0 0.0 0.0" xyz="1.0 0.0 0.25"/>
  </joint>
  <link name="chassis_link">
    <visual>
      <origin rpy="0.0 0.0 0.0" xyz="0.0 0.0 0.0"/>
      <geometry>
        <box size="1 0.5 0.25"/>
      </geometry>
    </visual>
    <collision>
      <origin rpy="0.0 0.0 0.0" xyz="0.0 0.0 0.0"/>
      <geometry>
        <box size="1 0.5 0.25"/>
      </geometry>
    </collision>
    <inertial>
      <origin rpy="0 0 0" xyz="0.0 0 0"/>
      <mass value="1"/>
      <inertia ixx="0.10416666666666666" ixy="0.0" ixz="0.0" iyy="0.35416666666666663" iyz="0.0" izz="0.41666666666666663"/>
    </inertial>
  </link>
  <!-- left wheel1 -->
  <joint name="chassis_to_left_wheel1_joint" type="continuous">
    <parent link="chassis_link"/>
    <child link="left_wheel1_link"/>
    <axis xyz="0 0 1"/>
    <origin rpy="-1.5707963267948966 0 0" xyz="0.6666666666666666 0.5714285714285714 -0.25"/>
  </joint>
  <link name="left_wheel1_link">
    <visual>
      <origin rpy="0.0 0.0 0.0" xyz="0.0 0.0 0.0"/>
      <geometry>
        <cylinder length="0.14285714285714285" radius="0.2"/>
      </geometry>
    </visual>
    <collision>
      <origin rpy="0.0 0.0 0.0" xyz="0.0 0.0 0.0"/>
      <geometry>
        <cylinder length="0.14285714285714285" radius="0.2"/>
      </geometry>
    </collision>
    <inertial>
      <origin rpy="0.0 0.0 0.0" xyz="0.0 0.0 0.0"/>
      <mass value="0.25"/>
      <inertia ixx="0.002925170068027211" ixy="0.0" ixz="0.0" iyy="0.002925170068027211" iyz="0.0" izz="0.005000000000000001"/>
    </inertial>
  </link>
  <!-- left wheel2 -->
  <joint name="chassis_to_left_wheel2_joint" type="continuous">
    <parent link="chassis_link"/>
    <child link="left_wheel2_link"/>
    <axis xyz="0 0 1"/>
    <origin rpy="-1.5707963267948966 0 0" xyz="-0.6666666666666666 0.5714285714285714 -0.25"/>
  </joint>
  <link name="left_wheel2_link">
    <visual>
      <origin rpy="0.0 0.0 0.0" xyz="0.0 0.0 0.0"/>
      <geometry>
        <cylinder length="0.14285714285714285" radius="0.2"/>
      </geometry>
    </visual>
    <collision>
      <origin rpy="0.0 0.0 0.0" xyz="0.0 0.0 0.0"/>
      <geometry>
        <cylinder length="0.14285714285714285" radius="0.2"/>
      </geometry>
    </collision>
    <inertial>
      <origin rpy="0.0 0.0 0.0" xyz="0.0 0.0 0.0"/>
      <mass value="0.25"/>
      <inertia ixx="0.002925170068027211" ixy="0.0" ixz="0.0" iyy="0.002925170068027211" iyz="0.0" izz="0.005000000000000001"/>
    </inertial>
  </link>
  <!-- right wheel1 -->
  <joint name="chassis_to_right_wheel1_joint" type="continuous">
    <parent link="chassis_link"/>
    <child link="right_wheel1_link"/>
    <axis xyz="0 0 -1"/>
    <origin rpy="1.5707963267948966 0 0" xyz="0.6666666666666666 -0.5714285714285714 -0.25"/>
  </joint>
  <link name="right_wheel1_link">
    <visual>
      <origin rpy="0.0 0.0 0.0" xyz="0.0 0.0 0.0"/>
      <geometry>
        <cylinder length="0.14285714285714285" radius="0.2"/>
      </geometry>
    </visual>
    <collision>
      <origin rpy="0.0 0.0 0.0" xyz="0.0 0.0 0.0"/>
      <geometry>
        <cylinder length="0.14285714285714285" radius="0.2"/>
      </geometry>
    </collision>
    <inertial>
      <origin rpy="0.0 0.0 0.0" xyz="0.0 0.0 0.0"/>
      <mass value="0.25"/>
      <inertia ixx="0.002925170068027211" ixy="0.0" ixz="0.0" iyy="0.002925170068027211" iyz="0.0" izz="0.005000000000000001"/>
    </inertial>
  </link>
  <!-- left wheel2 -->
  <joint name="chassis_to_right_wheel2_joint" type="continuous">
    <parent link="chassis_link"/>
    <child link="right_wheel2_link"/>
    <axis xyz="0 0 -1"/>
    <origin rpy="1.5707963267948966 0 0" xyz="-0.6666666666666666 -0.5714285714285714 -0.25"/>
  </joint>
  <link name="right_wheel2_link">
    <visual>
      <origin rpy="0.0 0.0 0.0" xyz="0.0 0.0 0.0"/>
      <geometry>
        <cylinder length="0.14285714285714285" radius="0.2"/>
      </geometry>
    </visual>
    <collision>
      <origin rpy="0.0 0.0 0.0" xyz="0.0 0.0 0.0"/>
      <geometry>
        <cylinder length="0.14285714285714285" radius="0.2"/>
      </geometry>
    </collision>
    <inertial>
      <origin rpy="0.0 0.0 0.0" xyz="0.0 0.0 0.0"/>
      <mass value="0.25"/>
      <inertia ixx="0.002925170068027211" ixy="0.0" ixz="0.0" iyy="0.002925170068027211" iyz="0.0" izz="0.005000000000000001"/>
    </inertial>
  </link>
  <joint name="chassis_to_camera_joint" type="fixed">
    <parent link="chassis_link"/>
    <child link="camera_link"/>
    <origin rpy="0.0 0.0 0.0" xyz="1.05 0 0.15"/>
  </joint>
  <link name="camera_link">
    <visual>
      <origin rpy="0.0 0.0 0.0" xyz="0.0 0.0 0.0"/>
      <geometry>
        <box size="0.1 0.2 0.2"/>
      </geometry>
    </visual>
    <inertial>
      <origin rpy="0 0 0" xyz="0.0 0 0"/>
      <mass value="0.1"/>
      <inertia ixx="0.0006666666666666668" ixy="0.0" ixz="0.0" iyy="0.00041666666666666675" iyz="0.0" izz="0.00041666666666666675"/>
    </inertial>
  </link>
</robot>
